2025-06-24 20:43:44,846 - ERROR - handle_exception:458 - Web介面錯誤: 404 Not Found: The requested URL was not found on the server. If you entered the URL manually please check your spelling and try again.
Traceback (most recent call last):
  File "C:\Users\user\anaconda3\envs\ROBOT\Lib\site-packages\flask\app.py", line 917, in full_dispatch_request
    rv = self.dispatch_request()
         ^^^^^^^^^^^^^^^^^^^^^^^
  File "C:\Users\user\anaconda3\envs\ROBOT\Lib\site-packages\flask\app.py", line 891, in dispatch_request
    self.raise_routing_exception(req)
  File "C:\Users\user\anaconda3\envs\ROBOT\Lib\site-packages\flask\app.py", line 500, in raise_routing_exception
    raise request.routing_exception  # type: ignore[misc]
    ^^^^^^^^^^^^^^^^^^^^^^^^^^^^^^^
  File "C:\Users\user\anaconda3\envs\ROBOT\Lib\site-packages\flask\ctx.py", line 362, in match_request
    result = self.url_adapter.match(return_rule=True)  # type: ignore
             ^^^^^^^^^^^^^^^^^^^^^^^^^^^^^^^^^^^^^^^^
  File "C:\Users\user\anaconda3\envs\ROBOT\Lib\site-packages\werkzeug\routing\map.py", line 629, in match
    raise NotFound() from None
werkzeug.exceptions.NotFound: 404 Not Found: The requested URL was not found on the server. If you entered the URL manually please check your spelling and try again.

2025-06-24 20:48:55,916 - ERROR - default_exception_handler:1785 - Task was destroyed but it is pending!
task: <Task pending name='Task-148396389' coro=<ServerRequestHandler.handle_request() running at C:\Users\user\anaconda3\envs\ROBOT\Lib\site-packages\pymodbus\server\requesthandler.py:95> cb=[_chain_future.<locals>._call_set_state() at C:\Users\user\anaconda3\envs\ROBOT\Lib\asyncio\futures.py:394]>
2025-06-24 20:48:55,917 - ERROR - default_exception_handler:1785 - Task was destroyed but it is pending!
task: <Task pending name='Task-148396390' coro=<ServerRequestHandler.handle_request() running at C:\Users\user\anaconda3\envs\ROBOT\Lib\site-packages\pymodbus\server\requesthandler.py:95> cb=[_chain_future.<locals>._call_set_state() at C:\Users\user\anaconda3\envs\ROBOT\Lib\asyncio\futures.py:394]>
2025-06-24 20:49:03,388 - ERROR - handle_exception:459 - Web介面錯誤: 404 Not Found: The requested URL was not found on the server. If you entered the URL manually please check your spelling and try again.
Traceback (most recent call last):
  File "C:\Users\user\anaconda3\envs\ROBOT\Lib\site-packages\flask\app.py", line 917, in full_dispatch_request
    rv = self.dispatch_request()
         ^^^^^^^^^^^^^^^^^^^^^^^
  File "C:\Users\user\anaconda3\envs\ROBOT\Lib\site-packages\flask\app.py", line 891, in dispatch_request
    self.raise_routing_exception(req)
  File "C:\Users\user\anaconda3\envs\ROBOT\Lib\site-packages\flask\app.py", line 500, in raise_routing_exception
    raise request.routing_exception  # type: ignore[misc]
    ^^^^^^^^^^^^^^^^^^^^^^^^^^^^^^^
  File "C:\Users\user\anaconda3\envs\ROBOT\Lib\site-packages\flask\ctx.py", line 362, in match_request
    result = self.url_adapter.match(return_rule=True)  # type: ignore
             ^^^^^^^^^^^^^^^^^^^^^^^^^^^^^^^^^^^^^^^^
  File "C:\Users\user\anaconda3\envs\ROBOT\Lib\site-packages\werkzeug\routing\map.py", line 629, in match
    raise NotFound() from None
werkzeug.exceptions.NotFound: 404 Not Found: The requested URL was not found on the server. If you entered the URL manually please check your spelling and try again.

2025-06-24 20:57:38,316 - ERROR - handle_exception:459 - Web介面錯誤: 404 Not Found: The requested URL was not found on the server. If you entered the URL manually please check your spelling and try again.
Traceback (most recent call last):
  File "C:\Users\user\anaconda3\envs\ROBOT\Lib\site-packages\flask\app.py", line 917, in full_dispatch_request
    rv = self.dispatch_request()
         ^^^^^^^^^^^^^^^^^^^^^^^
  File "C:\Users\user\anaconda3\envs\ROBOT\Lib\site-packages\flask\app.py", line 891, in dispatch_request
    self.raise_routing_exception(req)
  File "C:\Users\user\anaconda3\envs\ROBOT\Lib\site-packages\flask\app.py", line 500, in raise_routing_exception
    raise request.routing_exception  # type: ignore[misc]
    ^^^^^^^^^^^^^^^^^^^^^^^^^^^^^^^
  File "C:\Users\user\anaconda3\envs\ROBOT\Lib\site-packages\flask\ctx.py", line 362, in match_request
    result = self.url_adapter.match(return_rule=True)  # type: ignore
             ^^^^^^^^^^^^^^^^^^^^^^^^^^^^^^^^^^^^^^^^
  File "C:\Users\user\anaconda3\envs\ROBOT\Lib\site-packages\werkzeug\routing\map.py", line 629, in match
    raise NotFound() from None
werkzeug.exceptions.NotFound: 404 Not Found: The requested URL was not found on the server. If you entered the URL manually please check your spelling and try again.

2025-06-24 20:59:51,618 - ERROR - handle_exception:467 - Web介面錯誤: 404 Not Found: The requested URL was not found on the server. If you entered the URL manually please check your spelling and try again.
Traceback (most recent call last):
  File "C:\Users\user\anaconda3\envs\ROBOT\Lib\site-packages\flask\app.py", line 917, in full_dispatch_request
    rv = self.dispatch_request()
         ^^^^^^^^^^^^^^^^^^^^^^^
  File "C:\Users\user\anaconda3\envs\ROBOT\Lib\site-packages\flask\app.py", line 891, in dispatch_request
    self.raise_routing_exception(req)
  File "C:\Users\user\anaconda3\envs\ROBOT\Lib\site-packages\flask\app.py", line 500, in raise_routing_exception
    raise request.routing_exception  # type: ignore[misc]
    ^^^^^^^^^^^^^^^^^^^^^^^^^^^^^^^
  File "C:\Users\user\anaconda3\envs\ROBOT\Lib\site-packages\flask\ctx.py", line 362, in match_request
    result = self.url_adapter.match(return_rule=True)  # type: ignore
             ^^^^^^^^^^^^^^^^^^^^^^^^^^^^^^^^^^^^^^^^
  File "C:\Users\user\anaconda3\envs\ROBOT\Lib\site-packages\werkzeug\routing\map.py", line 629, in match
    raise NotFound() from None
werkzeug.exceptions.NotFound: 404 Not Found: The requested URL was not found on the server. If you entered the URL manually please check your spelling and try again.

2025-06-24 21:08:55,168 - ERROR - handle_exception:467 - Web介面錯誤: 404 Not Found: The requested URL was not found on the server. If you entered the URL manually please check your spelling and try again.
Traceback (most recent call last):
  File "C:\Users\user\anaconda3\envs\ROBOT\Lib\site-packages\flask\app.py", line 917, in full_dispatch_request
    rv = self.dispatch_request()
         ^^^^^^^^^^^^^^^^^^^^^^^
  File "C:\Users\user\anaconda3\envs\ROBOT\Lib\site-packages\flask\app.py", line 891, in dispatch_request
    self.raise_routing_exception(req)
  File "C:\Users\user\anaconda3\envs\ROBOT\Lib\site-packages\flask\app.py", line 500, in raise_routing_exception
    raise request.routing_exception  # type: ignore[misc]
    ^^^^^^^^^^^^^^^^^^^^^^^^^^^^^^^
  File "C:\Users\user\anaconda3\envs\ROBOT\Lib\site-packages\flask\ctx.py", line 362, in match_request
    result = self.url_adapter.match(return_rule=True)  # type: ignore
             ^^^^^^^^^^^^^^^^^^^^^^^^^^^^^^^^^^^^^^^^
  File "C:\Users\user\anaconda3\envs\ROBOT\Lib\site-packages\werkzeug\routing\map.py", line 629, in match
    raise NotFound() from None
werkzeug.exceptions.NotFound: 404 Not Found: The requested URL was not found on the server. If you entered the URL manually please check your spelling and try again.

2025-06-24 21:15:47,428 - ERROR - handle_exception:460 - Web介面錯誤: 404 Not Found: The requested URL was not found on the server. If you entered the URL manually please check your spelling and try again.
Traceback (most recent call last):
  File "C:\Users\user\anaconda3\envs\ROBOT\Lib\site-packages\flask\app.py", line 917, in full_dispatch_request
    rv = self.dispatch_request()
         ^^^^^^^^^^^^^^^^^^^^^^^
  File "C:\Users\user\anaconda3\envs\ROBOT\Lib\site-packages\flask\app.py", line 891, in dispatch_request
    self.raise_routing_exception(req)
  File "C:\Users\user\anaconda3\envs\ROBOT\Lib\site-packages\flask\app.py", line 500, in raise_routing_exception
    raise request.routing_exception  # type: ignore[misc]
    ^^^^^^^^^^^^^^^^^^^^^^^^^^^^^^^
  File "C:\Users\user\anaconda3\envs\ROBOT\Lib\site-packages\flask\ctx.py", line 362, in match_request
    result = self.url_adapter.match(return_rule=True)  # type: ignore
             ^^^^^^^^^^^^^^^^^^^^^^^^^^^^^^^^^^^^^^^^
  File "C:\Users\user\anaconda3\envs\ROBOT\Lib\site-packages\werkzeug\routing\map.py", line 629, in match
    raise NotFound() from None
werkzeug.exceptions.NotFound: 404 Not Found: The requested URL was not found on the server. If you entered the URL manually please check your spelling and try again.

2025-06-24 21:17:03,894 - ERROR - handle_exception:460 - Web介面錯誤: 404 Not Found: The requested URL was not found on the server. If you entered the URL manually please check your spelling and try again.
Traceback (most recent call last):
  File "C:\Users\user\anaconda3\envs\ROBOT\Lib\site-packages\flask\app.py", line 917, in full_dispatch_request
    rv = self.dispatch_request()
         ^^^^^^^^^^^^^^^^^^^^^^^
  File "C:\Users\user\anaconda3\envs\ROBOT\Lib\site-packages\flask\app.py", line 891, in dispatch_request
    self.raise_routing_exception(req)
  File "C:\Users\user\anaconda3\envs\ROBOT\Lib\site-packages\flask\app.py", line 500, in raise_routing_exception
    raise request.routing_exception  # type: ignore[misc]
    ^^^^^^^^^^^^^^^^^^^^^^^^^^^^^^^
  File "C:\Users\user\anaconda3\envs\ROBOT\Lib\site-packages\flask\ctx.py", line 362, in match_request
    result = self.url_adapter.match(return_rule=True)  # type: ignore
             ^^^^^^^^^^^^^^^^^^^^^^^^^^^^^^^^^^^^^^^^
  File "C:\Users\user\anaconda3\envs\ROBOT\Lib\site-packages\werkzeug\routing\map.py", line 629, in match
    raise NotFound() from None
werkzeug.exceptions.NotFound: 404 Not Found: The requested URL was not found on the server. If you entered the URL manually please check your spelling and try again.

2025-06-24 21:17:51,858 - ERROR - handle_exception:460 - Web介面錯誤: 404 Not Found: The requested URL was not found on the server. If you entered the URL manually please check your spelling and try again.
Traceback (most recent call last):
  File "C:\Users\user\anaconda3\envs\ROBOT\Lib\site-packages\flask\app.py", line 917, in full_dispatch_request
    rv = self.dispatch_request()
         ^^^^^^^^^^^^^^^^^^^^^^^
  File "C:\Users\user\anaconda3\envs\ROBOT\Lib\site-packages\flask\app.py", line 891, in dispatch_request
    self.raise_routing_exception(req)
  File "C:\Users\user\anaconda3\envs\ROBOT\Lib\site-packages\flask\app.py", line 500, in raise_routing_exception
    raise request.routing_exception  # type: ignore[misc]
    ^^^^^^^^^^^^^^^^^^^^^^^^^^^^^^^
  File "C:\Users\user\anaconda3\envs\ROBOT\Lib\site-packages\flask\ctx.py", line 362, in match_request
    result = self.url_adapter.match(return_rule=True)  # type: ignore
             ^^^^^^^^^^^^^^^^^^^^^^^^^^^^^^^^^^^^^^^^
  File "C:\Users\user\anaconda3\envs\ROBOT\Lib\site-packages\werkzeug\routing\map.py", line 629, in match
    raise NotFound() from None
werkzeug.exceptions.NotFound: 404 Not Found: The requested URL was not found on the server. If you entered the URL manually please check your spelling and try again.

2025-06-24 21:18:17,372 - ERROR - handle_exception:460 - Web介面錯誤: 404 Not Found: The requested URL was not found on the server. If you entered the URL manually please check your spelling and try again.
Traceback (most recent call last):
  File "C:\Users\user\anaconda3\envs\ROBOT\Lib\site-packages\flask\app.py", line 917, in full_dispatch_request
    rv = self.dispatch_request()
         ^^^^^^^^^^^^^^^^^^^^^^^
  File "C:\Users\user\anaconda3\envs\ROBOT\Lib\site-packages\flask\app.py", line 891, in dispatch_request
    self.raise_routing_exception(req)
  File "C:\Users\user\anaconda3\envs\ROBOT\Lib\site-packages\flask\app.py", line 500, in raise_routing_exception
    raise request.routing_exception  # type: ignore[misc]
    ^^^^^^^^^^^^^^^^^^^^^^^^^^^^^^^
  File "C:\Users\user\anaconda3\envs\ROBOT\Lib\site-packages\flask\ctx.py", line 362, in match_request
    result = self.url_adapter.match(return_rule=True)  # type: ignore
             ^^^^^^^^^^^^^^^^^^^^^^^^^^^^^^^^^^^^^^^^
  File "C:\Users\user\anaconda3\envs\ROBOT\Lib\site-packages\werkzeug\routing\map.py", line 629, in match
    raise NotFound() from None
werkzeug.exceptions.NotFound: 404 Not Found: The requested URL was not found on the server. If you entered the URL manually please check your spelling and try again.

2025-06-24 21:19:21,411 - ERROR - handle_exception:460 - Web介面錯誤: 404 Not Found: The requested URL was not found on the server. If you entered the URL manually please check your spelling and try again.
Traceback (most recent call last):
  File "C:\Users\user\anaconda3\envs\ROBOT\Lib\site-packages\flask\app.py", line 917, in full_dispatch_request
    rv = self.dispatch_request()
         ^^^^^^^^^^^^^^^^^^^^^^^
  File "C:\Users\user\anaconda3\envs\ROBOT\Lib\site-packages\flask\app.py", line 891, in dispatch_request
    self.raise_routing_exception(req)
  File "C:\Users\user\anaconda3\envs\ROBOT\Lib\site-packages\flask\app.py", line 500, in raise_routing_exception
    raise request.routing_exception  # type: ignore[misc]
    ^^^^^^^^^^^^^^^^^^^^^^^^^^^^^^^
  File "C:\Users\user\anaconda3\envs\ROBOT\Lib\site-packages\flask\ctx.py", line 362, in match_request
    result = self.url_adapter.match(return_rule=True)  # type: ignore
             ^^^^^^^^^^^^^^^^^^^^^^^^^^^^^^^^^^^^^^^^
  File "C:\Users\user\anaconda3\envs\ROBOT\Lib\site-packages\werkzeug\routing\map.py", line 629, in match
    raise NotFound() from None
werkzeug.exceptions.NotFound: 404 Not Found: The requested URL was not found on the server. If you entered the URL manually please check your spelling and try again.

2025-06-24 21:20:03,605 - ERROR - handle_exception:458 - Web介面錯誤: 404 Not Found: The requested URL was not found on the server. If you entered the URL manually please check your spelling and try again.
Traceback (most recent call last):
  File "C:\Users\user\anaconda3\envs\ROBOT\Lib\site-packages\flask\app.py", line 917, in full_dispatch_request
    rv = self.dispatch_request()
         ^^^^^^^^^^^^^^^^^^^^^^^
  File "C:\Users\user\anaconda3\envs\ROBOT\Lib\site-packages\flask\app.py", line 891, in dispatch_request
    self.raise_routing_exception(req)
  File "C:\Users\user\anaconda3\envs\ROBOT\Lib\site-packages\flask\app.py", line 500, in raise_routing_exception
    raise request.routing_exception  # type: ignore[misc]
    ^^^^^^^^^^^^^^^^^^^^^^^^^^^^^^^
  File "C:\Users\user\anaconda3\envs\ROBOT\Lib\site-packages\flask\ctx.py", line 362, in match_request
    result = self.url_adapter.match(return_rule=True)  # type: ignore
             ^^^^^^^^^^^^^^^^^^^^^^^^^^^^^^^^^^^^^^^^
  File "C:\Users\user\anaconda3\envs\ROBOT\Lib\site-packages\werkzeug\routing\map.py", line 629, in match
    raise NotFound() from None
werkzeug.exceptions.NotFound: 404 Not Found: The requested URL was not found on the server. If you entered the URL manually please check your spelling and try again.

2025-06-24 21:28:55,024 - ERROR - handle_exception:459 - Web介面錯誤: 404 Not Found: The requested URL was not found on the server. If you entered the URL manually please check your spelling and try again.
Traceback (most recent call last):
  File "C:\Users\user\anaconda3\envs\ROBOT\Lib\site-packages\flask\app.py", line 917, in full_dispatch_request
    rv = self.dispatch_request()
         ^^^^^^^^^^^^^^^^^^^^^^^
  File "C:\Users\user\anaconda3\envs\ROBOT\Lib\site-packages\flask\app.py", line 891, in dispatch_request
    self.raise_routing_exception(req)
  File "C:\Users\user\anaconda3\envs\ROBOT\Lib\site-packages\flask\app.py", line 500, in raise_routing_exception
    raise request.routing_exception  # type: ignore[misc]
    ^^^^^^^^^^^^^^^^^^^^^^^^^^^^^^^
  File "C:\Users\user\anaconda3\envs\ROBOT\Lib\site-packages\flask\ctx.py", line 362, in match_request
    result = self.url_adapter.match(return_rule=True)  # type: ignore
             ^^^^^^^^^^^^^^^^^^^^^^^^^^^^^^^^^^^^^^^^
  File "C:\Users\user\anaconda3\envs\ROBOT\Lib\site-packages\werkzeug\routing\map.py", line 629, in match
    raise NotFound() from None
werkzeug.exceptions.NotFound: 404 Not Found: The requested URL was not found on the server. If you entered the URL manually please check your spelling and try again.

